<robot name="Robot" version="1.0">
  <joint name="Wheel_1" type="continuous">
    <limit lower="0" upper="0" effort="0.00000" velocity="0.00000"/>
    <origin rpy="1.57080 0.00000 0.00000" xyz="1.00000 -0.75000 -0.70000"/>
    <parent link="Chasis_link"/>
    <child link="Wheel_Front_Right_link"/>
    <axis xyz="0.00000 0.00000 1.00000"/>
  </joint>
  <joint name="Wheel_2" type="continuous">
    <limit lower="0" upper="0" effort="0.00000" velocity="0.00000"/>
    <origin rpy="1.57080 0.00000 0.00000" xyz="-1.00000 -0.75000 -0.70000"/>
    <parent link="Chasis_link"/>
    <child link="Wheel_Rear_Left_link"/>
    <axis xyz="0.00000 0.00000 1.00000"/>
  </joint>
  <joint name="Wheel_3" type="continuous">
    <limit lower="0" upper="0" effort="0.00000" velocity="0.00000"/>
    <origin rpy="1.57080 0.00000 0.00000" xyz="1.00000 0.75000 -0.70000"/>
    <parent link="Chasis_link"/>
    <child link="Wheel_Front_Left_link"/>
    <axis xyz="0.00000 0.00000 1.00000"/>
  </joint>
  <joint name="Wheel_4" type="continuous">
    <limit lower="0" upper="0" effort="0.00000" velocity="0.00000"/>
    <origin rpy="1.57080 0.00000 0.00000" xyz="-1.00000 0.75000 -0.70000"/>
    <parent link="Chasis_link"/>
    <child link="Wheel_Rear_Right_link"/>
    <axis xyz="0.00000 0.00000 1.00000"/>
  </joint>
  <link name="Chasis_link">
    <collision name="Chasis_collision">
      <origin rpy="0.00000 0.00000 0.00000" xyz="0.00000 0.00000 0.00000"/>
      <geometry>
        <mesh filename="../meshes/dae/Cube.001.dae" scale="1.50000 1.10000 0.25000"/>
      </geometry>
    </collision>
    <visual name="Chasis">
      <origin rpy="0.00000 0.00000 0.00000" xyz="0.00000 0.00000 0.00000"/>
      <geometry>
        <mesh filename="../meshes/dae/Cube.001.dae" scale="1.50000 1.10000 0.25000"/>
      </geometry>
    </visual>
  </link>
  <link name="Wheel_Front_Left_link">
    <collision name="Wheel_Front_Left_collision">
      <origin rpy="-0.00000 0.00000 0.00000" xyz="0.00000 0.00000 0.00000"/>
      <geometry>
        <mesh filename="../meshes/dae/Torus.001.dae" scale="0.16000 0.16000 0.40000"/>
      </geometry>
    </collision>
    <visual name="Wheel_Front_Left">
      <origin rpy="0.00000 0.00000 0.00000" xyz="0.00000 0.00000 0.00000"/>
      <geometry>
        <mesh filename="../meshes/dae/Torus.001.dae" scale="0.16000 0.16000 0.40000"/>
      </geometry>
    </visual>
  </link>
  <link name="Wheel_Front_Right_link">
    <collision name="Wheel_Front_Right_collision">
      <origin rpy="-0.00000 0.00000 0.00000" xyz="0.00000 0.00000 -0.00000"/>
      <geometry>
        <mesh filename="../meshes/dae/Torus.dae" scale="0.16000 0.16000 0.40000"/>
      </geometry>
    </collision>
    <visual name="Wheel_Front_Right">
      <origin rpy="0.00000 0.00000 0.00000" xyz="0.00000 0.00000 -0.00000"/>
      <geometry>
        <mesh filename="../meshes/dae/Torus.dae" scale="0.16000 0.16000 0.40000"/>
      </geometry>
    </visual>
  </link>
  <link name="Wheel_Rear_Left_link">
    <collision name="Wheel_Rear_Left_collision">
      <origin rpy="-0.00000 0.00000 0.00000" xyz="0.00000 0.00000 -0.00000"/>
      <geometry>
        <mesh filename="../meshes/dae/Torus.003.dae" scale="0.16000 0.16000 0.40000"/>
      </geometry>
    </collision>
    <visual name="Wheel_Rear_Left">
      <origin rpy="0.00000 0.00000 0.00000" xyz="0.00000 0.00000 -0.00000"/>
      <geometry>
        <mesh filename="../meshes/dae/Torus.003.dae" scale="0.16000 0.16000 0.40000"/>
      </geometry>
    </visual>
  </link>
  <link name="Wheel_Rear_Right_link">
    <collision name="Wheel_Rear_Right_collision">
      <origin rpy="-0.00000 0.00000 0.00000" xyz="0.00000 0.00000 0.00000"/>
      <geometry>
        <mesh filename="../meshes/dae/Torus.002.dae" scale="0.16000 0.16000 0.40000"/>
      </geometry>
    </collision>
    <visual name="Wheel_Rear_Right">
      <origin rpy="0.00000 0.00000 0.00000" xyz="0.00000 0.00000 0.00000"/>
      <geometry>
        <mesh filename="../meshes/dae/Torus.002.dae" scale="0.16000 0.16000 0.40000"/>
      </geometry>
    </visual>
  </link>
</robot>