<robot name="Final Robot" version="1.0">
  <joint name="Arm_Link_1" type="revolute">
    <limit lower="-1.57000" upper="10.00000" effort="0.00000" velocity="0.00000"/>
    <origin rpy="-1.57080 1.57080 0.00000" xyz="-0.00205 -0.00000 0.24982"/>
    <parent link="Arm_Base_link"/>
    <child link="Arm_Link_1_link"/>
    <axis xyz="0.00000 0.00000 1.00000"/>
  </joint>
  <joint name="Arm_Link_2" type="revolute">
    <limit lower="-5.00000" upper="5.00000" effort="0.00000" velocity="0.00000"/>
    <origin rpy="0.00000 0.00000 1.54609" xyz="-0.99754 0.00174 -0.00000"/>
    <parent link="Arm_Link_1_link"/>
    <child link="Arm_Link_2_link"/>
    <axis xyz="0.00000 0.00000 1.00000"/>
  </joint>
  <joint name="Base_Arm" type="revolute">
    <limit lower="-10.00000" upper="10.00000" effort="0.00000" velocity="0.00000"/>
    <origin rpy="0.00000 0.78540 0.00000" xyz="0.47162 0.00259 -0.16401"/>
    <parent link="Chasis_link"/>
    <child link="Arm_Base_link"/>
    <axis xyz="0.00000 0.00000 1.00000"/>
  </joint>
  <joint name="Gripper_1" type="revolute">
    <limit lower="0.00000" upper="3.00000" effort="0.00000" velocity="0.00000"/>
    <origin rpy="-1.57080 -1.56905 0.00000" xyz="0.30521 -0.00000 -0.00053"/>
    <parent link="Effector_Base_link"/>
    <child link="Grip_1_link"/>
    <axis xyz="0.00000 0.00000 1.00000"/>
  </joint>
  <joint name="Gripper_2" type="revolute">
    <limit lower="-3.00000" upper="0.00000" effort="0.00000" velocity="0.00000"/>
    <origin rpy="1.56905 0.00000 -1.57080" xyz="-0.00000 -0.30521 0.00000"/>
    <parent link="Effector_Base_link"/>
    <child link="Grip_2_link"/>
    <axis xyz="0.00000 0.00000 1.00000"/>
  </joint>
  <joint name="Gripper_3" type="revolute">
    <limit lower="-3.00000" upper="0.00000" effort="0.00000" velocity="0.00000"/>
    <origin rpy="1.57083 1.56905 -3.14156" xyz="-0.30521 -0.00000 0.00053"/>
    <parent link="Effector_Base_link"/>
    <child link="Grip_3_link"/>
    <axis xyz="0.00000 0.00000 1.00000"/>
  </joint>
  <joint name="Gripper_4" type="revolute">
    <limit lower="0.00000" upper="3.00000" effort="0.00000" velocity="0.00000"/>
    <origin rpy="-1.56905 -0.00000 1.57080" xyz="-0.00000 0.30521 0.00000"/>
    <parent link="Effector_Base_link"/>
    <child link="Grip_4_link"/>
    <axis xyz="0.00000 0.00000 1.00000"/>
  </joint>
  <joint name="Gripper_Base" type="continuous">
    <limit lower="0" upper="0" effort="0.00000" velocity="0.00000"/>
    <origin rpy="1.57080 -0.00000 -1.57254" xyz="-1.05000 0.00096 -0.00000"/>
    <parent link="Arm_Link_2_link"/>
    <child link="Effector_Base_link"/>
    <axis xyz="0.00000 0.00000 1.00000"/>
  </joint>
  <joint name="Lid" type="revolute">
    <limit lower="0.00000" upper="1.60000" effort="0.00000" velocity="0.00000"/>
    <origin rpy="1.57080 0.00000 0.00000" xyz="-1.14192 -0.00004 0.12451"/>
    <parent link="Chasis_link"/>
    <child link="Lid_link"/>
    <axis xyz="0.00000 0.00000 1.00000"/>
  </joint>
  <joint name="Wheel_1" type="continuous">
    <limit lower="0" upper="0" effort="0.00000" velocity="0.00000"/>
    <origin rpy="1.57080 0.00000 0.00000" xyz="-0.92500 0.75000 -1.35074"/>
    <parent link="Chasis_link"/>
    <child link="Wheel_Rear_Right_link"/>
    <axis xyz="0.00000 0.00000 1.00000"/>
  </joint>
  <joint name="Wheel_2" type="continuous">
    <limit lower="0" upper="0" effort="0.00000" velocity="0.00000"/>
    <origin rpy="1.57080 0.00000 0.00000" xyz="-0.92500 -0.75000 -1.35074"/>
    <parent link="Chasis_link"/>
    <child link="Wheel_Rear_Left_link"/>
    <axis xyz="0.00000 0.00000 1.00000"/>
  </joint>
  <joint name="Wheel_3" type="continuous">
    <limit lower="0" upper="0" effort="0.00000" velocity="0.00000"/>
    <origin rpy="1.57080 0.00000 0.00000" xyz="1.07500 -0.75000 -1.35074"/>
    <parent link="Chasis_link"/>
    <child link="Wheel_Front_Right_link"/>
    <axis xyz="0.00000 0.00000 1.00000"/>
  </joint>
  <joint name="Wheel_4" type="continuous">
    <limit lower="0" upper="0" effort="0.00000" velocity="0.00000"/>
    <origin rpy="1.57080 0.00000 0.00000" xyz="1.07500 0.75000 -1.35074"/>
    <parent link="Chasis_link"/>
    <child link="Wheel_Front_Left_link"/>
    <axis xyz="0.00000 0.00000 1.00000"/>
  </joint>
  <link name="Arm_Base_link">
    <collision name="Arm Base_collision">
      <origin rpy="0.00000 -0.00000 0.00000" xyz="-0.00000 0.00000 -0.00000"/>
      <geometry>
        <mesh filename="../meshes/dae/Cube.001.dae" scale="0.05000 0.05000 0.26617"/>
      </geometry>
    </collision>
    <inertial>
      <inertia ixx="0.00200" ixy="0.00000" ixz="0.00000" iyy="0.00200" iyz="0.00000" izz="0.00200"/>
      <origin rpy="0.00000 0.00000 0.00000" xyz="0.00000 0.00000 -0.00000"/>
      <mass value="1.00000"/>
    </inertial>
    <visual name="Arm Base">
      <origin rpy="0.00000 0.00000 0.00000" xyz="0.00000 0.00000 -0.00000"/>
      <geometry>
        <box size="0.10064 0.10000 0.50000"/>
      </geometry>
    </visual>
  </link>
  <link name="Arm_Link_1_link">
    <collision name="Arm Link 1_collision">
      <origin rpy="1.57080 0.00000 -1.57080" xyz="-0.50000 0.00000 0.00000"/>
      <geometry>
        <mesh filename="../meshes/dae/Cube.004.dae" scale="0.05000 0.05000 2.52691"/>
      </geometry>
    </collision>
    <inertial>
      <inertia ixx="0.00200" ixy="0.00000" ixz="0.00000" iyy="0.00200" iyz="0.00000" izz="0.00200"/>
      <origin rpy="0.00000 0.00000 0.00000" xyz="0.00000 -0.00000 0.00000"/>
      <mass value="1.00000"/>
    </inertial>
    <visual name="Arm Link 1">
      <origin rpy="1.57080 0.00000 -1.57254" xyz="-0.50000 0.00000 0.00000"/>
      <geometry>
        <box size="0.10006 0.10000 1.00000"/>
      </geometry>
    </visual>
  </link>
  <link name="Arm_Link_2_link">
    <collision name="Arm Link 2_collision">
      <origin rpy="1.57080 -0.00000 -1.57080" xyz="-0.50000 0.00000 0.00000"/>
      <geometry>
        <mesh filename="../meshes/dae/Cube.005.dae" scale="0.05000 0.05000 2.52691"/>
      </geometry>
    </collision>
    <inertial>
      <inertia ixx="0.00200" ixy="0.00000" ixz="-0.00000" iyy="0.00200" iyz="-0.00000" izz="0.00200"/>
      <origin rpy="0.00000 0.00000 0.00000" xyz="-0.00000 0.00000 0.00000"/>
      <mass value="0.20000"/>
    </inertial>
    <visual name="Arm Link 2">
      <origin rpy="1.57080 -0.00000 -1.57254" xyz="-0.50000 0.00000 0.00000"/>
      <geometry>
        <box size="0.10006 0.10000 1.00000"/>
      </geometry>
    </visual>
  </link>
  <link name="Chasis_link">
    <collision name="Chasis_collision">
      <origin rpy="0.00000 0.00000 0.00000" xyz="0.00000 0.00000 0.00000"/>
      <geometry>
        <mesh filename="../meshes/dae/Cube.012.dae" scale="1.31027 0.99102 0.01250"/>
      </geometry>
    </collision>
    <inertial>
      <inertia ixx="0.01600" ixy="0.00000" ixz="0.00000" iyy="0.01600" iyz="0.00000" izz="0.01600"/>
      <origin rpy="0.00000 0.00000 0.00000" xyz="0.00000 0.00000 0.00000"/>
      <mass value="51.00000"/>
    </inertial>
    <visual name="Chasis">
      <origin rpy="0.00000 0.00000 0.00000" xyz="0.00000 0.00000 0.00000"/>
      <geometry>
        <mesh filename="../meshes/dae/Cube.012.dae" scale="1.31027 0.99102 0.01250"/>
      </geometry>
    </visual>
  </link>
  <link name="Effector_Base_link">
    <collision name="Effector Base_collision">
      <origin rpy="0.00000 0.00175 -0.00000" xyz="-0.00000 0.00000 0.00000"/>
      <geometry>
        <mesh filename="../meshes/dae/Cube.264.dae" scale="0.05000 0.05000 0.25269"/>
      </geometry>
    </collision>
    <inertial>
      <inertia ixx="0.00800" ixy="-0.00000" ixz="-0.00000" iyy="0.00800" iyz="-0.00000" izz="0.00800"/>
      <origin rpy="0.00000 0.00000 0.00000" xyz="-0.00000 -0.00000 -0.00000"/>
      <mass value="0.80000"/>
    </inertial>
    <visual name="Effector Base">
      <origin rpy="0.00000 -0.00000 -0.00000" xyz="0.00000 0.00000 0.00000"/>
      <geometry>
        <mesh filename="../meshes/dae/Cube.264.dae" scale="0.05000 0.05000 0.25269"/>
      </geometry>
    </visual>
  </link>
  <link name="Grip_1_link">
    <collision name="Grip 1_collision">
      <origin rpy="1.57080 -0.00000 1.57080" xyz="-0.00000 -0.00000 -0.00000"/>
      <geometry>
        <mesh filename="../meshes/dae/Cube.266.dae" scale="0.05000 0.05000 0.05000"/>
      </geometry>
    </collision>
    <visual name="Grip 1">
      <origin rpy="1.57080 -0.00000 1.57080" xyz="-0.00000 -0.00000 -0.00000"/>
      <geometry>
        <mesh filename="../meshes/dae/Cube.266.dae" scale="0.05000 0.05000 0.05000"/>
      </geometry>
    </visual>
  </link>
  <link name="Grip_2_link">
    <collision name="Grip 2_collision">
      <origin rpy="-1.57080 0.00000 0.00000" xyz="-0.00000 -0.00000 0.00000"/>
      <geometry>
        <mesh filename="../meshes/dae/Cube.270.dae" scale="0.05000 0.05000 0.05000"/>
      </geometry>
    </collision>
    <visual name="Grip 2">
      <origin rpy="-1.57080 -0.00000 -0.00000" xyz="-0.00000 -0.00000 0.00000"/>
      <geometry>
        <mesh filename="../meshes/dae/Cube.270.dae" scale="0.05000 0.05000 0.05000"/>
      </geometry>
    </visual>
  </link>
  <link name="Grip_3_link">
    <collision name="Grip 3_collision">
      <origin rpy="-1.57080 0.00000 1.57080" xyz="0.00000 0.00000 0.00000"/>
      <geometry>
        <mesh filename="../meshes/dae/Cube.268.dae" scale="0.05000 0.05000 0.05000"/>
      </geometry>
    </collision>
    <visual name="Grip 3">
      <origin rpy="-1.57080 0.00000 1.57080" xyz="0.00000 0.00000 0.00000"/>
      <geometry>
        <mesh filename="../meshes/dae/Cube.268.dae" scale="0.05000 0.05000 0.05000"/>
      </geometry>
    </visual>
  </link>
  <link name="Grip_4_link">
    <collision name="Grip 4_collision">
      <origin rpy="1.57080 -0.00000 0.00000" xyz="-0.00000 0.00000 0.00000"/>
      <geometry>
        <mesh filename="../meshes/dae/Cube.269.dae" scale="0.05000 0.05000 0.05000"/>
      </geometry>
    </collision>
    <visual name="Grip 4">
      <origin rpy="1.57080 -0.00000 0.00000" xyz="-0.00000 0.00000 0.00000"/>
      <geometry>
        <mesh filename="../meshes/dae/Cube.269.dae" scale="0.05000 0.05000 0.05000"/>
      </geometry>
    </visual>
  </link>
  <link name="Lid_link">
    <collision name="Lid_collision">
      <origin rpy="-1.57080 0.00000 0.00000" xyz="0.00000 0.00000 0.00000"/>
      <geometry>
        <mesh filename="../meshes/dae/Cube.015.dae" scale="1.31027 0.99102 0.01250"/>
      </geometry>
    </collision>
  </link>
  <link name="Wheel_Front_Left_link">
    <collision name="Wheel_Front_Left_collision">
      <origin rpy="0.00000 0.00000 0.00000" xyz="0.00000 0.00000 0.00000"/>
      <geometry>
        <mesh filename="../meshes/dae/Torus.001.dae" scale="0.16000 0.16000 0.40000"/>
      </geometry>
    </collision>
    <visual name="Wheel_Front_Left">
      <origin rpy="0.00000 0.00000 0.00000" xyz="0.00000 0.00000 0.00000"/>
      <geometry>
        <mesh filename="../meshes/dae/Torus.001.dae" scale="0.16000 0.16000 0.40000"/>
      </geometry>
    </visual>
  </link>
  <link name="Wheel_Front_Right_link">
    <collision name="Wheel_Front_Right_collision">
      <origin rpy="0.00000 0.00000 0.00000" xyz="0.00000 0.00000 -0.00000"/>
      <geometry>
        <mesh filename="../meshes/dae/Torus.dae" scale="0.16000 0.16000 0.40000"/>
      </geometry>
    </collision>
    <visual name="Wheel_Front_Right">
      <origin rpy="0.00000 0.00000 0.00000" xyz="0.00000 0.00000 -0.00000"/>
      <geometry>
        <mesh filename="../meshes/dae/Torus.dae" scale="0.16000 0.16000 0.40000"/>
      </geometry>
    </visual>
  </link>
  <link name="Wheel_Rear_Left_link">
    <collision name="Wheel_Rear_Left_collision">
      <origin rpy="0.00000 0.00000 0.00000" xyz="0.00000 0.00000 -0.00000"/>
      <geometry>
        <mesh filename="../meshes/dae/Torus.003.dae" scale="0.16000 0.16000 0.40000"/>
      </geometry>
    </collision>
    <visual name="Wheel_Rear_Left">
      <origin rpy="0.00000 0.00000 0.00000" xyz="0.00000 0.00000 -0.00000"/>
      <geometry>
        <mesh filename="../meshes/dae/Torus.003.dae" scale="0.16000 0.16000 0.40000"/>
      </geometry>
    </visual>
  </link>
  <link name="Wheel_Rear_Right_link">
    <collision name="Wheel_Rear_Right_collision">
      <origin rpy="0.00000 0.00000 0.00000" xyz="0.00000 0.00000 0.00000"/>
      <geometry>
        <mesh filename="../meshes/dae/Torus.002.dae" scale="0.16000 0.16000 0.40000"/>
      </geometry>
    </collision>
    <visual name="Wheel_Rear_Right">
      <origin rpy="0.00000 0.00000 0.00000" xyz="0.00000 0.00000 0.00000"/>
      <geometry>
        <mesh filename="../meshes/dae/Torus.002.dae" scale="0.16000 0.16000 0.40000"/>
      </geometry>
    </visual>
  </link>
</robot>